

import { catchError } from "../middelware/catchError.js"
import { User } from "../../../database/models/user.model.js"
import { AppError } from "../../utilts/appError.js"
import { deleteOne } from "../handlers/handlers.js"




 const addUser = catchError(async (req , res , next)=>{
let user = new User(req.body)
 await user.save()
 res.json({message: "success" , user})
         
    })
      
     
 const getAllUser = catchError( async (req , res)=>{
  let user = await User.find()
 res.json({message: "success" , user})
  })
            

const getUser = catchError( async (req , res , next)=>{
let user = await User.findById(req.params.id)
 user || next(new AppError('user not found' , 404))
!user || res.json({message: "success" , user})
 })


 const updateUser = catchError(async (req , res)=>{
let user = await User.findByIdAndUpdate(req.params.id, req.body , {new: true})
user || next(new AppError('user not found' , 404))
!user || res.json({message: "success" , user})
   })
      
const deleteUser = deleteOne(User)    
        





 export{
    addUser,
    getAllUser,
    getUser,
    updateUser,
    deleteUser
  
 }